Exception on /exportlogs [GET]
Traceback (most recent call last):
  File "/Users/anushkaswarup/miniconda3/envs/predictPAM/lib/python3.6/site-packages/flask/app.py", line 2446, in wsgi_app
    response = self.full_dispatch_request()
  File "/Users/anushkaswarup/miniconda3/envs/predictPAM/lib/python3.6/site-packages/flask/app.py", line 1951, in full_dispatch_request
    rv = self.handle_user_exception(e)
  File "/Users/anushkaswarup/miniconda3/envs/predictPAM/lib/python3.6/site-packages/flask/app.py", line 1820, in handle_user_exception
    reraise(exc_type, exc_value, tb)
  File "/Users/anushkaswarup/miniconda3/envs/predictPAM/lib/python3.6/site-packages/flask/_compat.py", line 39, in reraise
    raise value
  File "/Users/anushkaswarup/miniconda3/envs/predictPAM/lib/python3.6/site-packages/flask/app.py", line 1949, in full_dispatch_request
    rv = self.dispatch_request()
  File "/Users/anushkaswarup/miniconda3/envs/predictPAM/lib/python3.6/site-packages/flask/app.py", line 1935, in dispatch_request
    return self.view_functions[rule.endpoint](**req.view_args)
  File "/Users/anushkaswarup/Downloads/Storage/EPI/predictPAM-WebApp/flask/app/app.py", line 133, in exportlogs
    with open(server.log, "r") as file:
NameError: name 'server' is not defined
Exception on /exportlogs [GET]
Traceback (most recent call last):
  File "/Users/anushkaswarup/miniconda3/envs/predictPAM/lib/python3.6/site-packages/flask/app.py", line 2446, in wsgi_app
    response = self.full_dispatch_request()
  File "/Users/anushkaswarup/miniconda3/envs/predictPAM/lib/python3.6/site-packages/flask/app.py", line 1951, in full_dispatch_request
    rv = self.handle_user_exception(e)
  File "/Users/anushkaswarup/miniconda3/envs/predictPAM/lib/python3.6/site-packages/flask/app.py", line 1820, in handle_user_exception
    reraise(exc_type, exc_value, tb)
  File "/Users/anushkaswarup/miniconda3/envs/predictPAM/lib/python3.6/site-packages/flask/_compat.py", line 39, in reraise
    raise value
  File "/Users/anushkaswarup/miniconda3/envs/predictPAM/lib/python3.6/site-packages/flask/app.py", line 1949, in full_dispatch_request
    rv = self.dispatch_request()
  File "/Users/anushkaswarup/miniconda3/envs/predictPAM/lib/python3.6/site-packages/flask/app.py", line 1935, in dispatch_request
    return self.view_functions[rule.endpoint](**req.view_args)
  File "/Users/anushkaswarup/Downloads/Storage/EPI/predictPAM-WebApp/flask/app/app.py", line 136, in exportlogs
    resp = make_response(log)
  File "/Users/anushkaswarup/miniconda3/envs/predictPAM/lib/python3.6/site-packages/flask/helpers.py", line 223, in make_response
    return current_app.make_response(args)
  File "/Users/anushkaswarup/miniconda3/envs/predictPAM/lib/python3.6/site-packages/flask/app.py", line 2130, in make_response
    " {rv.__class__.__name__}.".format(rv=rv)
TypeError: The view function did not return a valid response. The return type must be a string, dict, tuple, Response instance, or WSGI callable, but it was a list.
Exception on /exportlogs [GET]
Traceback (most recent call last):
  File "/Users/anushkaswarup/miniconda3/envs/predictPAM/lib/python3.6/site-packages/flask/app.py", line 2446, in wsgi_app
    response = self.full_dispatch_request()
  File "/Users/anushkaswarup/miniconda3/envs/predictPAM/lib/python3.6/site-packages/flask/app.py", line 1951, in full_dispatch_request
    rv = self.handle_user_exception(e)
  File "/Users/anushkaswarup/miniconda3/envs/predictPAM/lib/python3.6/site-packages/flask/app.py", line 1820, in handle_user_exception
    reraise(exc_type, exc_value, tb)
  File "/Users/anushkaswarup/miniconda3/envs/predictPAM/lib/python3.6/site-packages/flask/_compat.py", line 39, in reraise
    raise value
  File "/Users/anushkaswarup/miniconda3/envs/predictPAM/lib/python3.6/site-packages/flask/app.py", line 1949, in full_dispatch_request
    rv = self.dispatch_request()
  File "/Users/anushkaswarup/miniconda3/envs/predictPAM/lib/python3.6/site-packages/flask/app.py", line 1935, in dispatch_request
    return self.view_functions[rule.endpoint](**req.view_args)
  File "/Users/anushkaswarup/Downloads/Storage/EPI/predictPAM-WebApp/flask/app/app.py", line 137, in exportlogs
    si = StringIO.StringIO()
NameError: name 'StringIO' is not defined
Exception on /exportlogs [GET]
Traceback (most recent call last):
  File "/Users/anushkaswarup/miniconda3/envs/predictPAM/lib/python3.6/site-packages/flask/app.py", line 2446, in wsgi_app
    response = self.full_dispatch_request()
  File "/Users/anushkaswarup/miniconda3/envs/predictPAM/lib/python3.6/site-packages/flask/app.py", line 1951, in full_dispatch_request
    rv = self.handle_user_exception(e)
  File "/Users/anushkaswarup/miniconda3/envs/predictPAM/lib/python3.6/site-packages/flask/app.py", line 1820, in handle_user_exception
    reraise(exc_type, exc_value, tb)
  File "/Users/anushkaswarup/miniconda3/envs/predictPAM/lib/python3.6/site-packages/flask/_compat.py", line 39, in reraise
    raise value
  File "/Users/anushkaswarup/miniconda3/envs/predictPAM/lib/python3.6/site-packages/flask/app.py", line 1949, in full_dispatch_request
    rv = self.dispatch_request()
  File "/Users/anushkaswarup/miniconda3/envs/predictPAM/lib/python3.6/site-packages/flask/app.py", line 1935, in dispatch_request
    return self.view_functions[rule.endpoint](**req.view_args)
  File "/Users/anushkaswarup/Downloads/Storage/EPI/predictPAM-WebApp/flask/app/app.py", line 138, in exportlogs
    si = io.StringIO.StringIO()
AttributeError: type object '_io.StringIO' has no attribute 'StringIO'
Exception on /exportlogs [GET]
Traceback (most recent call last):
  File "/Users/anushkaswarup/miniconda3/envs/predictPAM/lib/python3.6/site-packages/flask/app.py", line 2446, in wsgi_app
    response = self.full_dispatch_request()
  File "/Users/anushkaswarup/miniconda3/envs/predictPAM/lib/python3.6/site-packages/flask/app.py", line 1951, in full_dispatch_request
    rv = self.handle_user_exception(e)
  File "/Users/anushkaswarup/miniconda3/envs/predictPAM/lib/python3.6/site-packages/flask/app.py", line 1820, in handle_user_exception
    reraise(exc_type, exc_value, tb)
  File "/Users/anushkaswarup/miniconda3/envs/predictPAM/lib/python3.6/site-packages/flask/_compat.py", line 39, in reraise
    raise value
  File "/Users/anushkaswarup/miniconda3/envs/predictPAM/lib/python3.6/site-packages/flask/app.py", line 1949, in full_dispatch_request
    rv = self.dispatch_request()
  File "/Users/anushkaswarup/miniconda3/envs/predictPAM/lib/python3.6/site-packages/flask/app.py", line 1935, in dispatch_request
    return self.view_functions[rule.endpoint](**req.view_args)
  File "/Users/anushkaswarup/Downloads/Storage/EPI/predictPAM-WebApp/flask/app/app.py", line 138, in exportlogs
    si = StringIO.StringIO()
AttributeError: type object '_io.StringIO' has no attribute 'StringIO'
Exception on /exportlogs [GET]
Traceback (most recent call last):
  File "/Users/anushkaswarup/miniconda3/envs/predictPAM/lib/python3.6/site-packages/flask/app.py", line 2446, in wsgi_app
    response = self.full_dispatch_request()
  File "/Users/anushkaswarup/miniconda3/envs/predictPAM/lib/python3.6/site-packages/flask/app.py", line 1951, in full_dispatch_request
    rv = self.handle_user_exception(e)
  File "/Users/anushkaswarup/miniconda3/envs/predictPAM/lib/python3.6/site-packages/flask/app.py", line 1820, in handle_user_exception
    reraise(exc_type, exc_value, tb)
  File "/Users/anushkaswarup/miniconda3/envs/predictPAM/lib/python3.6/site-packages/flask/_compat.py", line 39, in reraise
    raise value
  File "/Users/anushkaswarup/miniconda3/envs/predictPAM/lib/python3.6/site-packages/flask/app.py", line 1949, in full_dispatch_request
    rv = self.dispatch_request()
  File "/Users/anushkaswarup/miniconda3/envs/predictPAM/lib/python3.6/site-packages/flask/app.py", line 1935, in dispatch_request
    return self.view_functions[rule.endpoint](**req.view_args)
  File "/Users/anushkaswarup/Downloads/Storage/EPI/predictPAM-WebApp/flask/app/app.py", line 139, in exportlogs
    cw = csv.writer(si)
NameError: name 'csv' is not defined
